<sdf version='1.7'>
  <world name='default'>
    <light name='sun' type='directional'>
      <cast_shadows>1</cast_shadows>
      <pose>0 0 10 0 -0 0</pose>
      <diffuse>0.8 0.8 0.8 1</diffuse>
      <specular>0.2 0.2 0.2 1</specular>
      <attenuation>
        <range>1000</range>
        <constant>0.9</constant>
        <linear>0.01</linear>
        <quadratic>0.001</quadratic>
      </attenuation>
      <direction>-0.5 0.1 -0.9</direction>
      <spot>
        <inner_angle>0</inner_angle>
        <outer_angle>0</outer_angle>
        <falloff>0</falloff>
      </spot>
    </light>
    <model name='ground_plane'>
      <static>1</static>
      <link name='link'>
        <collision name='collision'>
          <geometry>
            <plane>
              <normal>0 0 1</normal>
              <size>100 100</size>
            </plane>
          </geometry>
          <surface>
            <friction>
              <ode>
                <mu>100</mu>
                <mu2>50</mu2>
              </ode>
              <torsional>
                <ode/>
              </torsional>
            </friction>
            <contact>
              <ode/>
            </contact>
            <bounce/>
          </surface>
          <max_contacts>10</max_contacts>
        </collision>
        <visual name='visual'>
          <cast_shadows>0</cast_shadows>
          <geometry>
            <plane>
              <normal>0 0 1</normal>
              <size>100 100</size>
            </plane>
          </geometry>
          <material>
            <script>
              <uri>file://media/materials/scripts/gazebo.material</uri>
              <name>Gazebo/Grey</name>
            </script>
          </material>
        </visual>
        <self_collide>0</self_collide>
        <enable_wind>0</enable_wind>
        <kinematic>0</kinematic>
      </link>
    </model>
    <gravity>0 0 -9.8</gravity>
    <magnetic_field>6e-06 2.3e-05 -4.2e-05</magnetic_field>
    <atmosphere type='adiabatic'/>
    <physics type='ode'>
      <max_step_size>0.001</max_step_size>
      <real_time_factor>1</real_time_factor>
      <real_time_update_rate>1000</real_time_update_rate>
    </physics>
    <scene>
      <ambient>0.4 0.4 0.4 1</ambient>
      <background>0.7 0.7 0.7 1</background>
      <shadows>1</shadows>
    </scene>
    <wind/>
    <spherical_coordinates>
      <surface_model>EARTH_WGS84</surface_model>
      <latitude_deg>0</latitude_deg>
      <longitude_deg>0</longitude_deg>
      <elevation>0</elevation>
      <heading_deg>0</heading_deg>
    </spherical_coordinates>
    <state world_name='default'>
      <sim_time>864 502000000</sim_time>
      <real_time>317 679017474</real_time>
      <wall_time>1732086495 173360812</wall_time>
      <iterations>315763</iterations>
      <model name='aws_robomaker_residential_TVCabinet_01'>
        <pose>1.63163 1.32196 0 0 -0 0.489331</pose>
        <scale>1 1 1</scale>
        <link name='link'>
          <pose>1.63163 1.32196 0 0 -0 0.489331</pose>
          <velocity>0 0 0 0 -0 0</velocity>
          <acceleration>0 0 0 0 -0 0</acceleration>
          <wrench>0 0 0 0 -0 0</wrench>
        </link>
      </model>
      <model name='aws_robomaker_residential_TVCabinet_01_clone'>
        <pose>0.645253 -0.375935 0 0 -0 1.58292</pose>
        <scale>1 1 1</scale>
        <link name='link'>
          <pose>0.645253 -0.375935 0 0 -0 1.58292</pose>
          <velocity>0 0 0 0 -0 0</velocity>
          <acceleration>0 0 0 0 -0 0</acceleration>
          <wrench>0 0 0 0 -0 0</wrench>
        </link>
      </model>
      <model name='diablo'>
        <pose>0.478648 0.338294 0.200002 -1e-06 0.00123 1.52282</pose>
        <scale>1 1 1</scale>
        <link name='back_caster'>
          <pose>0.471924 0.198271 0.050174 -0.116625 0.00123 1.52282</pose>
          <velocity>7.8e-05 0.000988 1.8e-05 0.001027 -0.000182 4.6e-05</velocity>
          <acceleration>0.121235 1.40009 0.00752 2.96817 -0.142586 -0.049777</acceleration>
          <wrench>0.001212 0.014001 7.5e-05 0 -0 0</wrench>
        </link>
        <link name='base_link'>
          <pose>0.478648 0.338294 0.200002 -1e-06 0.00123 1.52282</pose>
          <velocity>5.7e-05 0.000834 0.000163 0.001028 -9.6e-05 4.7e-05</velocity>
          <acceleration>-0.005158 -0.170211 0.477922 2.14535 -0.308495 -0.041885</acceleration>
          <wrench>-0.078704 -2.59743 7.29308 0 -0 0</wrench>
        </link>
        <link name='drivewhl_l_link'>
          <pose>0.298849 0.346803 0.1 -0.000146 1.40589 1.52268</pose>
          <velocity>-3.9e-05 0.000689 -0.000119 -0.006418 -0.000397 0.001549</velocity>
          <acceleration>-0.1368 0.677331 -0.256649 -0.011312 -0.201176 0.471322</acceleration>
          <wrench>-0.0684 0.338666 -0.128325 0 -0 0</wrench>
        </link>
        <link name='drivewhl_r_link'>
          <pose>0.658434 0.329537 0.1 4e-05 1.2015 1.52284</pose>
          <velocity>9.9e-05 0.000715 -0.000118 -0.00667 0.000959 -0.001525</velocity>
          <acceleration>0.190371 0.682419 -0.254725 0.135796 -0.319458 -0.733341</acceleration>
          <wrench>0.095186 0.34121 -0.127362 0 -0 0</wrench>
        </link>
        <link name='front_caster'>
          <pose>0.485353 0.477946 0.050021 0.714708 0.001317 1.52282</pose>
          <velocity>4.7e-05 0.000657 0.027259 -0.012573 0.000915 4.6e-05</velocity>
          <acceleration>0.095268 0.633062 65.9868 -2.9783 1.35003 -0.049593</acceleration>
          <wrench>0.000953 0.006331 0.659868 0 -0 0</wrench>
        </link>
      </model>
      <model name='ground_plane'>
        <pose>0 0 0 0 -0 0</pose>
        <scale>1 1 1</scale>
        <link name='link'>
          <pose>0 0 0 0 -0 0</pose>
          <velocity>0 0 0 0 -0 0</velocity>
          <acceleration>0 0 0 0 -0 0</acceleration>
          <wrench>0 0 0 0 -0 0</wrench>
        </link>
      </model>
      <model name='unit_box'>
        <pose>-1.38585 0.967809 0.499995 -1e-05 -0 0.414188</pose>
        <scale>1 1 1</scale>
        <link name='link'>
          <pose>-1.38585 0.967809 0.499995 -1e-05 -0 0.414188</pose>
          <velocity>0 0 0 0 -0 0</velocity>
          <acceleration>-0.008989 0.00841 -9.78131 -0.016624 -0.017157 0.000582</acceleration>
          <wrench>-0.008989 0.00841 -9.78131 0 -0 0</wrench>
        </link>
      </model>
      <model name='unit_box_clone'>
        <pose>-0.46765 1.36404 0.499995 1e-05 -0 0.414185</pose>
        <scale>1 1 1</scale>
        <link name='link'>
          <pose>-0.46765 1.36404 0.499995 1e-05 -0 0.414185</pose>
          <velocity>0 0 0 0 -0 0</velocity>
          <acceleration>0.008989 -0.00841 -9.78131 0.016624 0.017157 0.000582</acceleration>
          <wrench>0.008989 -0.00841 -9.78131 0 -0 0</wrench>
        </link>
      </model>
      <model name='unit_box_clone_0'>
        <pose>-1.26485 -0.54956 0.499995 0 1e-05 -0.013518</pose>
        <scale>1 1 1</scale>
        <link name='link'>
          <pose>-1.26485 -0.54956 0.499995 0 1e-05 -0.013518</pose>
          <velocity>0 0 0 0 -0 0</velocity>
          <acceleration>0.010513 -0.0062 -9.78234 0.012397 0.021027 3e-06</acceleration>
          <wrench>0.010513 -0.0062 -9.78234 0 -0 0</wrench>
        </link>
      </model>
      <model name='unit_box_clone_0_clone'>
        <pose>0.016502 2.71453 0.499995 -1e-05 -0 0.412801</pose>
        <scale>1 1 1</scale>
        <link name='link'>
          <pose>0.016502 2.71453 0.499995 -1e-05 -0 0.412801</pose>
          <velocity>0 0 0 0 -0 0</velocity>
          <acceleration>-0.008977 0.008418 -9.78132 -0.016639 -0.017128 0.000585</acceleration>
          <wrench>-0.008977 0.008418 -9.78132 0 -0 0</wrench>
        </link>
      </model>
      <light name='sun'>
        <pose>0 0 10 0 -0 0</pose>
      </light>
    </state>
    <gui fullscreen='0'>
      <camera name='user_camera'>
        <pose>1.34958 -0.324731 10.0041 2.8e-05 1.5698 1.53619</pose>
        <view_controller>orbit</view_controller>
        <projection_type>perspective</projection_type>
      </camera>
    </gui>
    <audio>
      <device>default</device>
    </audio>
    <model name='diablo'>
      <link name='base_link'>
        <inertial>
          <pose>0.017738 0.000102 0.380982 1.5708 -0 1.5708</pose>
          <mass>15.26</mass>
          <inertia>
            <ixx>0.372959</ixx>
            <ixy>-9.96391e-06</ixy>
            <ixz>3.01407e-07</ixz>
            <iyy>0.344225</iyy>
            <iyz>0.000801119</iyz>
            <izz>0.27115</izz>
          </inertia>
        </inertial>
        <collision name='base_link_collision'>
          <pose>0 0 0 0 -0 0</pose>
          <geometry>
            <box>
              <size>0.42 0.31 0.3</size>
            </box>
          </geometry>
          <max_contacts>10</max_contacts>
          <surface>
            <contact>
              <ode/>
            </contact>
            <bounce/>
            <friction>
              <torsional>
                <ode/>
              </torsional>
              <ode/>
            </friction>
          </surface>
        </collision>
        <collision name='base_link_fixed_joint_lump__camera_link_collision_1'>
          <pose>0.215 0 0.05 0 -0 0</pose>
          <geometry>
            <box>
              <size>0.015 0.13 0.022</size>
            </box>
          </geometry>
          <surface>
            <contact>
              <ode/>
            </contact>
            <friction>
              <ode/>
              <torsional>
                <ode/>
              </torsional>
            </friction>
            <bounce/>
          </surface>
          <max_contacts>10</max_contacts>
        </collision>
        <collision name='base_link_fixed_joint_lump__imu_link_collision_2'>
          <pose>0 0 0.01 0 -0 0</pose>
          <geometry>
            <box>
              <size>0.1 0.1 0.1</size>
            </box>
          </geometry>
          <surface>
            <contact>
              <ode/>
            </contact>
            <friction>
              <ode/>
              <torsional>
                <ode/>
              </torsional>
            </friction>
            <bounce/>
          </surface>
          <max_contacts>10</max_contacts>
        </collision>
        <collision name='base_link_fixed_joint_lump__lidar_link_collision_3'>
          <pose>0 0 0 0 -0 0</pose>
          <geometry>
            <cylinder>
              <length>0.055</length>
              <radius>0.0508</radius>
            </cylinder>
          </geometry>
          <surface>
            <contact>
              <ode/>
            </contact>
            <friction>
              <ode/>
              <torsional>
                <ode/>
              </torsional>
            </friction>
            <bounce/>
          </surface>
          <max_contacts>10</max_contacts>
        </collision>
        <visual name='base_link_visual'>
          <pose>0 0 0 3.14159 -0 0</pose>
          <geometry>
            <box>
              <size>0.42 0.31 0.3</size>
            </box>
          </geometry>
        </visual>
        <visual name='base_link_fixed_joint_lump__camera_link_visual_1'>
          <pose>0.215 0 0.05 0 -0 0</pose>
          <geometry>
            <box>
              <size>0.015 0.13 0.022</size>
            </box>
          </geometry>
        </visual>
        <visual name='base_link_fixed_joint_lump__imu_link_visual_2'>
          <pose>0 0 0.01 0 -0 0</pose>
          <geometry>
            <box>
              <size>0.1 0.1 0.1</size>
            </box>
          </geometry>
        </visual>
        <visual name='base_link_fixed_joint_lump__lidar_link_visual_3'>
          <pose>0 0 0.18 0 -0 0</pose>
          <geometry>
            <cylinder>
              <length>0.055</length>
              <radius>0.0508</radius>
            </cylinder>
          </geometry>
        </visual>
        <sensor name='depth_camera' type='depth'>
          <visualize>1</visualize>
          <update_rate>30</update_rate>
          <camera name='camera'>
            <horizontal_fov>1.0472</horizontal_fov>
            <image>
              <width>640</width>
              <height>480</height>
              <format>R8G8B8</format>
            </image>
            <clip>
              <near>0.05</near>
              <far>3</far>
            </clip>
          </camera>
          <plugin name='depth_camera_controller' filename='libgazebo_ros_camera.so'>
            <baseline>0.2</baseline>
            <alwaysOn>1</alwaysOn>
            <updateRate>0.0</updateRate>
            <frame_name>camera_depth_frame</frame_name>
            <pointCloudCutoff>0.5</pointCloudCutoff>
            <pointCloudCutoffMax>3.0</pointCloudCutoffMax>
            <distortionK1>0</distortionK1>
            <distortionK2>0</distortionK2>
            <distortionK3>0</distortionK3>
            <distortionT1>0</distortionT1>
            <distortionT2>0</distortionT2>
            <CxPrime>0</CxPrime>
            <Cx>0</Cx>
            <Cy>0</Cy>
            <focalLength>0</focalLength>
            <hackBaseline>0</hackBaseline>
          </plugin>
          <pose>0.215 0 0.05 0 -0 0</pose>
        </sensor>
        <sensor name='imu_sensor' type='imu'>
          <plugin name='imu_plugin' filename='libgazebo_ros_imu_sensor.so'>
            <ros>
              <namespace>/diablo</namespace>
              <remapping>~/out:=imu</remapping>
            </ros>
            <initial_orientation_as_reference>0</initial_orientation_as_reference>
          </plugin>
          <always_on>1</always_on>
          <update_rate>100</update_rate>
          <visualize>1</visualize>
          <imu>
            <angular_velocity>
              <x>
                <noise type='gaussian'>
                  <mean>0</mean>
                  <stddev>0.0002</stddev>
                  <bias_mean>7.5e-06</bias_mean>
                  <bias_stddev>8e-07</bias_stddev>
                </noise>
              </x>
              <y>
                <noise type='gaussian'>
                  <mean>0</mean>
                  <stddev>0.0002</stddev>
                  <bias_mean>7.5e-06</bias_mean>
                  <bias_stddev>8e-07</bias_stddev>
                </noise>
              </y>
              <z>
                <noise type='gaussian'>
                  <mean>0</mean>
                  <stddev>0.0002</stddev>
                  <bias_mean>7.5e-06</bias_mean>
                  <bias_stddev>8e-07</bias_stddev>
                </noise>
              </z>
            </angular_velocity>
            <linear_acceleration>
              <x>
                <noise type='gaussian'>
                  <mean>0</mean>
                  <stddev>0.017</stddev>
                  <bias_mean>0.1</bias_mean>
                  <bias_stddev>0.001</bias_stddev>
                </noise>
              </x>
              <y>
                <noise type='gaussian'>
                  <mean>0</mean>
                  <stddev>0.017</stddev>
                  <bias_mean>0.1</bias_mean>
                  <bias_stddev>0.001</bias_stddev>
                </noise>
              </y>
              <z>
                <noise type='gaussian'>
                  <mean>0</mean>
                  <stddev>0.017</stddev>
                  <bias_mean>0.1</bias_mean>
                  <bias_stddev>0.001</bias_stddev>
                </noise>
              </z>
            </linear_acceleration>
          </imu>
          <pose>0 0 0.01 0 -0 0</pose>
        </sensor>
        <sensor name='velodyne-VLP16' type='ray'>
          <visualize>0</visualize>
          <update_rate>10</update_rate>
          <ray>
            <scan>
              <horizontal>
                <samples>440</samples>
                <resolution>1</resolution>
                <min_angle>-3.14159</min_angle>
                <max_angle>3.14159</max_angle>
              </horizontal>
              <vertical>
                <samples>16</samples>
                <resolution>1</resolution>
                <min_angle>-0.261799</min_angle>
                <max_angle>0.261799</max_angle>
              </vertical>
            </scan>
            <range>
              <min>0.3</min>
              <max>5</max>
              <resolution>0.001</resolution>
            </range>
            <noise>
              <type>gaussian</type>
              <mean>0</mean>
              <stddev>0</stddev>
            </noise>
          </ray>
          <plugin name='gazebo_ros_laser_controller' filename='libgazebo_ros_velodyne_laser.so'>
            <topicName>/velodyne_points</topicName>
            <frameName>lidar_link</frameName>
            <min_range>0.3</min_range>
            <max_range>1.5</max_range>
            <gaussianNoise>0.008</gaussianNoise>
          </plugin>
          <pose>0 0 0 0 -0 0</pose>
        </sensor>
        <self_collide>0</self_collide>
        <enable_wind>0</enable_wind>
        <kinematic>0</kinematic>
      </link>
      <joint name='caster2_joint' type='revolute'>
        <pose relative_to='base_link'>-0.14 0 -0.15 0 -0 0</pose>
        <parent>base_link</parent>
        <child>back_caster</child>
        <axis>
          <xyz>1 0 0</xyz>
          <limit>
            <lower>-1e+16</lower>
            <upper>1e+16</upper>
          </limit>
          <dynamics>
            <spring_reference>0</spring_reference>
            <spring_stiffness>0</spring_stiffness>
          </dynamics>
        </axis>
      </joint>
      <link name='back_caster'>
        <pose relative_to='caster2_joint'>0 0 0 0 -0 0</pose>
        <inertial>
          <pose>0 0 0 0 -0 0</pose>
          <mass>0.01</mass>
          <inertia>
            <ixx>1e-05</ixx>
            <ixy>0</ixy>
            <ixz>0</ixz>
            <iyy>1e-05</iyy>
            <iyz>0</iyz>
            <izz>1e-05</izz>
          </inertia>
        </inertial>
        <collision name='back_caster_collision'>
          <pose>0 0 0 0 -0 0</pose>
          <geometry>
            <sphere>
              <radius>0.05</radius>
            </sphere>
          </geometry>
          <max_contacts>10</max_contacts>
          <surface>
            <contact>
              <ode/>
            </contact>
            <bounce/>
            <friction>
              <torsional>
                <ode/>
              </torsional>
              <ode/>
            </friction>
          </surface>
        </collision>
        <visual name='back_caster_visual'>
          <pose>0 0 0 0 -0 0</pose>
          <geometry>
            <sphere>
              <radius>0.05</radius>
            </sphere>
          </geometry>
        </visual>
        <self_collide>0</self_collide>
        <enable_wind>0</enable_wind>
        <kinematic>0</kinematic>
      </link>
      <joint name='caster_joint' type='revolute'>
        <pose relative_to='base_link'>0.14 0 -0.15 0 -0 0</pose>
        <parent>base_link</parent>
        <child>front_caster</child>
        <axis>
          <xyz>1 0 0</xyz>
          <limit>
            <lower>-1e+16</lower>
            <upper>1e+16</upper>
          </limit>
          <dynamics>
            <spring_reference>0</spring_reference>
            <spring_stiffness>0</spring_stiffness>
          </dynamics>
        </axis>
      </joint>
      <link name='front_caster'>
        <pose relative_to='caster_joint'>0 0 0 0 -0 0</pose>
        <inertial>
          <pose>0 0 0 0 -0 0</pose>
          <mass>0.01</mass>
          <inertia>
            <ixx>1e-05</ixx>
            <ixy>0</ixy>
            <ixz>0</ixz>
            <iyy>1e-05</iyy>
            <iyz>0</iyz>
            <izz>1e-05</izz>
          </inertia>
        </inertial>
        <collision name='front_caster_collision'>
          <pose>0 0 0 0 -0 0</pose>
          <geometry>
            <sphere>
              <radius>0.05</radius>
            </sphere>
          </geometry>
          <max_contacts>10</max_contacts>
          <surface>
            <contact>
              <ode/>
            </contact>
            <bounce/>
            <friction>
              <torsional>
                <ode/>
              </torsional>
              <ode/>
            </friction>
          </surface>
        </collision>
        <visual name='front_caster_visual'>
          <pose>0 0 0 0 -0 0</pose>
          <geometry>
            <sphere>
              <radius>0.05</radius>
            </sphere>
          </geometry>
        </visual>
        <self_collide>0</self_collide>
        <enable_wind>0</enable_wind>
        <kinematic>0</kinematic>
      </link>
      <joint name='drivewhl_l_joint' type='revolute'>
        <pose relative_to='base_link'>0 0.18 -0.1 0 -0 0</pose>
        <parent>base_link</parent>
        <child>drivewhl_l_link</child>
        <axis>
          <xyz>0 1 0</xyz>
          <limit>
            <lower>-1e+16</lower>
            <upper>1e+16</upper>
          </limit>
          <dynamics>
            <spring_reference>0</spring_reference>
            <spring_stiffness>0</spring_stiffness>
          </dynamics>
        </axis>
      </joint>
      <link name='drivewhl_l_link'>
        <pose relative_to='drivewhl_l_joint'>0 0 0 0 -0 0</pose>
        <inertial>
          <pose>0 0 0 1.5708 -0 0</pose>
          <mass>0.5</mass>
          <inertia>
            <ixx>0.00131667</ixx>
            <ixy>0</ixy>
            <ixz>0</ixz>
            <iyy>0.00131667</iyy>
            <iyz>0</iyz>
            <izz>0.0025</izz>
          </inertia>
        </inertial>
        <collision name='drivewhl_l_link_collision'>
          <pose>0 0 0 1.5708 -0 0</pose>
          <geometry>
            <cylinder>
              <length>0.04</length>
              <radius>0.1</radius>
            </cylinder>
          </geometry>
          <max_contacts>10</max_contacts>
          <surface>
            <contact>
              <ode/>
            </contact>
            <bounce/>
            <friction>
              <torsional>
                <ode/>
              </torsional>
              <ode/>
            </friction>
          </surface>
        </collision>
        <visual name='drivewhl_l_link_visual'>
          <pose>0 0 0 1.5708 -0 0</pose>
          <geometry>
            <cylinder>
              <length>0.04</length>
              <radius>0.1</radius>
            </cylinder>
          </geometry>
        </visual>
        <self_collide>0</self_collide>
        <enable_wind>0</enable_wind>
        <kinematic>0</kinematic>
      </link>
      <joint name='drivewhl_r_joint' type='revolute'>
        <pose relative_to='base_link'>0 -0.18 -0.1 0 -0 0</pose>
        <parent>base_link</parent>
        <child>drivewhl_r_link</child>
        <axis>
          <xyz>0 1 0</xyz>
          <limit>
            <lower>-1e+16</lower>
            <upper>1e+16</upper>
          </limit>
          <dynamics>
            <spring_reference>0</spring_reference>
            <spring_stiffness>0</spring_stiffness>
          </dynamics>
        </axis>
      </joint>
      <link name='drivewhl_r_link'>
        <pose relative_to='drivewhl_r_joint'>0 0 0 0 -0 0</pose>
        <inertial>
          <pose>0 0 0 1.5708 -0 0</pose>
          <mass>0.5</mass>
          <inertia>
            <ixx>0.00131667</ixx>
            <ixy>0</ixy>
            <ixz>0</ixz>
            <iyy>0.00131667</iyy>
            <iyz>0</iyz>
            <izz>0.0025</izz>
          </inertia>
        </inertial>
        <collision name='drivewhl_r_link_collision'>
          <pose>0 0 0 1.5708 -0 0</pose>
          <geometry>
            <cylinder>
              <length>0.04</length>
              <radius>0.1</radius>
            </cylinder>
          </geometry>
          <max_contacts>10</max_contacts>
          <surface>
            <contact>
              <ode/>
            </contact>
            <bounce/>
            <friction>
              <torsional>
                <ode/>
              </torsional>
              <ode/>
            </friction>
          </surface>
        </collision>
        <visual name='drivewhl_r_link_visual'>
          <pose>0 0 0 1.5708 -0 0</pose>
          <geometry>
            <cylinder>
              <length>0.04</length>
              <radius>0.1</radius>
            </cylinder>
          </geometry>
        </visual>
        <self_collide>0</self_collide>
        <enable_wind>0</enable_wind>
        <kinematic>0</kinematic>
      </link>
      <static>0</static>
      <plugin name='diff_drive' filename='libgazebo_ros_diff_drive.so'>
        <ros>
          <namespace>/diablo</namespace>
          <remap from='cmd_vel' to='/cmd_vel'/>
        </ros>
        <left_joint>drivewhl_l_joint</left_joint>
        <right_joint>drivewhl_r_joint</right_joint>
        <wheel_separation>0.4</wheel_separation>
        <wheel_diameter>0.2</wheel_diameter>
        <max_wheel_torque>20</max_wheel_torque>
        <max_wheel_acceleration>1.0</max_wheel_acceleration>
        <publish_odom>1</publish_odom>
        <publish_odom_tf>1</publish_odom_tf>
        <publish_wheel_tf>1</publish_wheel_tf>
        <odometry_frame>odom</odometry_frame>
        <robot_base_frame>base_link</robot_base_frame>
      </plugin>
      <pose>0.45 -8.6 0.2 0 -0 1.57</pose>
    </model>
    <model name='unit_box'>
      <pose>-0.383049 1.7296 0.5 0 -0 0</pose>
      <link name='link'>
        <inertial>
          <mass>1</mass>
          <inertia>
            <ixx>0.166667</ixx>
            <ixy>0</ixy>
            <ixz>0</ixz>
            <iyy>0.166667</iyy>
            <iyz>0</iyz>
            <izz>0.166667</izz>
          </inertia>
          <pose>0 0 0 0 -0 0</pose>
        </inertial>
        <collision name='collision'>
          <geometry>
            <box>
              <size>1 1 1</size>
            </box>
          </geometry>
          <max_contacts>10</max_contacts>
          <surface>
            <contact>
              <ode/>
            </contact>
            <bounce/>
            <friction>
              <torsional>
                <ode/>
              </torsional>
              <ode/>
            </friction>
          </surface>
        </collision>
        <visual name='visual'>
          <geometry>
            <box>
              <size>1 1 1</size>
            </box>
          </geometry>
          <material>
            <script>
              <name>Gazebo/Grey</name>
              <uri>file://media/materials/scripts/gazebo.material</uri>
            </script>
          </material>
        </visual>
        <self_collide>0</self_collide>
        <enable_wind>0</enable_wind>
        <kinematic>0</kinematic>
      </link>
    </model>
    <model name='unit_box_clone'>
      <pose>-0.182322 1.27229 0.5 0 -0 0.298295</pose>
      <link name='link'>
        <inertial>
          <mass>1</mass>
          <inertia>
            <ixx>0.166667</ixx>
            <ixy>0</ixy>
            <ixz>0</ixz>
            <iyy>0.166667</iyy>
            <iyz>0</iyz>
            <izz>0.166667</izz>
          </inertia>
          <pose>0 0 0 0 -0 0</pose>
        </inertial>
        <collision name='collision'>
          <geometry>
            <box>
              <size>1 1 1</size>
            </box>
          </geometry>
          <max_contacts>10</max_contacts>
          <surface>
            <contact>
              <ode/>
            </contact>
            <bounce/>
            <friction>
              <torsional>
                <ode/>
              </torsional>
              <ode/>
            </friction>
          </surface>
        </collision>
        <visual name='visual'>
          <geometry>
            <box>
              <size>1 1 1</size>
            </box>
          </geometry>
          <material>
            <script>
              <name>Gazebo/Grey</name>
              <uri>file://media/materials/scripts/gazebo.material</uri>
            </script>
          </material>
        </visual>
        <self_collide>0</self_collide>
        <enable_wind>0</enable_wind>
        <kinematic>0</kinematic>
      </link>
    </model>
    <model name='aws_robomaker_residential_TVCabinet_01'>
      <link name='link'>
        <inertial>
          <mass>59.2</mass>
          <inertia>
            <ixx>30.4</ixx>
            <ixy>0</ixy>
            <ixz>0</ixz>
            <iyy>2.56</iyy>
            <iyz>0</iyz>
            <izz>31.38</izz>
          </inertia>
        </inertial>
        <collision name='collision'>
          <geometry>
            <mesh>
              <uri>model://aws_robomaker_residential_TVCabinet_01/meshes/aws_TVCabinet_01_collision.DAE</uri>
              <scale>1 1 1</scale>
            </mesh>
          </geometry>
          <max_contacts>10</max_contacts>
          <surface>
            <contact>
              <ode/>
            </contact>
            <bounce/>
            <friction>
              <torsional>
                <ode/>
              </torsional>
              <ode/>
            </friction>
          </surface>
        </collision>
        <visual name='visual'>
          <geometry>
            <mesh>
              <uri>model://aws_robomaker_residential_TVCabinet_01/meshes/aws_TVCabinet_01_visual.DAE</uri>
            </mesh>
          </geometry>
          <meta>
            <layer>1</layer>
          </meta>
        </visual>
        <self_collide>0</self_collide>
        <enable_wind>0</enable_wind>
        <kinematic>0</kinematic>
      </link>
      <static>1</static>
      <pose>1.9686 0.522359 0 0 -0 0</pose>
    </model>
    <model name='aws_robomaker_residential_TVCabinet_01_clone'>
      <link name='link'>
        <inertial>
          <mass>59.2</mass>
          <inertia>
            <ixx>30.4</ixx>
            <ixy>0</ixy>
            <ixz>0</ixz>
            <iyy>2.56</iyy>
            <iyz>0</iyz>
            <izz>31.38</izz>
          </inertia>
        </inertial>
        <collision name='collision'>
          <geometry>
            <mesh>
              <uri>model://aws_robomaker_residential_TVCabinet_01/meshes/aws_TVCabinet_01_collision.DAE</uri>
              <scale>1 1 1</scale>
            </mesh>
          </geometry>
          <max_contacts>10</max_contacts>
          <surface>
            <contact>
              <ode/>
            </contact>
            <bounce/>
            <friction>
              <torsional>
                <ode/>
              </torsional>
              <ode/>
            </friction>
          </surface>
        </collision>
        <visual name='visual'>
          <geometry>
            <mesh>
              <uri>model://aws_robomaker_residential_TVCabinet_01/meshes/aws_TVCabinet_01_visual.DAE</uri>
            </mesh>
          </geometry>
          <meta>
            <layer>1</layer>
          </meta>
        </visual>
        <self_collide>0</self_collide>
        <enable_wind>0</enable_wind>
        <kinematic>0</kinematic>
      </link>
      <static>1</static>
      <pose>0.796926 -1.29822 0 0 -0 0.489331</pose>
    </model>
    <model name='unit_box_clone_0'>
      <pose>-1.55882 -0.69019 0.499995 1e-05 -0 0.41419</pose>
      <link name='link'>
        <inertial>
          <mass>1</mass>
          <inertia>
            <ixx>0.166667</ixx>
            <ixy>0</ixy>
            <ixz>0</ixz>
            <iyy>0.166667</iyy>
            <iyz>0</iyz>
            <izz>0.166667</izz>
          </inertia>
          <pose>0 0 0 0 -0 0</pose>
        </inertial>
        <collision name='collision'>
          <geometry>
            <box>
              <size>1 1 1</size>
            </box>
          </geometry>
          <max_contacts>10</max_contacts>
          <surface>
            <contact>
              <ode/>
            </contact>
            <bounce/>
            <friction>
              <torsional>
                <ode/>
              </torsional>
              <ode/>
            </friction>
          </surface>
        </collision>
        <visual name='visual'>
          <geometry>
            <box>
              <size>1 1 1</size>
            </box>
          </geometry>
          <material>
            <script>
              <name>Gazebo/Grey</name>
              <uri>file://media/materials/scripts/gazebo.material</uri>
            </script>
          </material>
        </visual>
        <self_collide>0</self_collide>
        <enable_wind>0</enable_wind>
        <kinematic>0</kinematic>
      </link>
    </model>
    <model name='unit_box_clone_0_clone'>
      <pose>0.145277 3.00873 0.5 0 -0 -0.013518</pose>
      <link name='link'>
        <inertial>
          <mass>1</mass>
          <inertia>
            <ixx>0.166667</ixx>
            <ixy>0</ixy>
            <ixz>0</ixz>
            <iyy>0.166667</iyy>
            <iyz>0</iyz>
            <izz>0.166667</izz>
          </inertia>
          <pose>0 0 0 0 -0 0</pose>
        </inertial>
        <collision name='collision'>
          <geometry>
            <box>
              <size>1 1 1</size>
            </box>
          </geometry>
          <max_contacts>10</max_contacts>
          <surface>
            <contact>
              <ode/>
            </contact>
            <bounce/>
            <friction>
              <torsional>
                <ode/>
              </torsional>
              <ode/>
            </friction>
          </surface>
        </collision>
        <visual name='visual'>
          <geometry>
            <box>
              <size>1 1 1</size>
            </box>
          </geometry>
          <material>
            <script>
              <name>Gazebo/Grey</name>
              <uri>file://media/materials/scripts/gazebo.material</uri>
            </script>
          </material>
        </visual>
        <self_collide>0</self_collide>
        <enable_wind>0</enable_wind>
        <kinematic>0</kinematic>
      </link>
    </model>
  </world>
</sdf>
